<?xml version="1.0" ?>
<!-- =================================================================================== -->
<!-- |    This document was autogenerated by xacro from /home/ckreis/mil2/install/subjugator_description/share/subjugator_description/urdf/sub9_sim.urdf.xacro | -->
<!-- |    EDITING THIS FILE BY HAND IS NOT RECOMMENDED                                 | -->
<!-- =================================================================================== -->
<robot name="sub9" xmlns:experimental="http://sdformat.org/schemas/experimental" xmlns:gz="http://gazebosim.org/schema">
  <!-- Base Link of the Sub -->
  <link name="base_link">
    <!-- Sub's Pose -->
    <origin rpy="0 0 0" xyz="0 0 0"/>
    <!-- Inertial Properties -->
    <inertial>
      <origin rpy="0 0 0" xyz="0.352 0 0"/>
      <!-- Need to be properly calculated at some point -->
      <mass value="20.5"/>
      <inertia ixx="2.4" ixy="0" ixz="0" iyy="2.4" iyz="0.0" izz="3.0"/>
    </inertial>
    <!-- Visual Data-->
    <visual name="visual">
      <origin rpy="0 0 0" xyz="0 0 0"/>
      <geometry>
        <mesh filename="package://subjugator_description/urdf/meshes/Sub9.dae"/>
      </geometry>
    </visual>
    <!-- Collision Data -->
    <collision name="buoyancy_collision">
      <!-- This collision is for calculating the buoyant forces-->
      <origin rpy="0 0 0" xyz="0.354 0 0"/>
      <geometry>
        <sphere radius="0.1695"/>
      </geometry>
    </collision>
    <!-- The following are shell collisions. They dont contrubute to buoyancy-->
    <!-- and are for collisions -->
    <collision name="Front_Shell">
      <origin rpy="0 0 0" xyz="0.708 0 0"/>
      <geometry>
        <box size="0.001 0.345 0.345"/>
      </geometry>
    </collision>
    <collision name="Back_Shell">
      <origin rpy="0 0 0" xyz="0 0 0"/>
      <geometry>
        <box size="0.001 0.345 0.345"/>
      </geometry>
    </collision>
    <collision name="Left_Shell">
      <origin rpy="0 0 0" xyz="0.345 0.177 0"/>
      <geometry>
        <box size="0.708 0.001 0.345"/>
      </geometry>
    </collision>
    <collision name="Right_Shell">
      <origin rpy="0 0 0" xyz="0.345 -0.177 0"/>
      <geometry>
        <box size="0.708 0.001 0.345"/>
      </geometry>
    </collision>
    <collision name="Top_Shell">
      <origin rpy="0 0 0" xyz="0.345 0 0.177"/>
      <geometry>
        <box size="0.708 0.345 0.001"/>
      </geometry>
    </collision>
    <collision name="Front_Shell">
      <origin rpy="0 0 0" xyz="0.345 0 -0.177"/>
      <geometry>
        <box size="0.708 0.345 0.001"/>
      </geometry>
    </collision>
  </link>
  <gazebo>
    <plugin filename="gz-sim-hydrodynamics-system" name="gz::sim::systems::Hydrodynamics">
      <link_name>localization_center</link_name>
      <xU>-30</xU>
      <xUabsU>-15</xUabsU>
      <yV>-40</yV>
      <yVabsV>-25</yVabsV>
      <zW>-50</zW>
      <zWabsW>-25</zWabsW>
      <kP>-30</kP>
      <kPabsP>-8</kPabsP>
      <mQ>-35</mQ>
      <mQabsQ>-10</mQabsQ>
      <nR>-40</nR>
      <nRabsR>-20</nRabsR>
    </plugin>
    <plugin filename="ThrusterBridge" name="thrusterBridge::ThrusterBridge"/>
    <plugin filename="MarbleDropper" name="marble_dropper::MarbleDropper"/>
    <plugin filename="GripperControl" name="gripper_control::GripperControl">
      <left_joint_name>gripper_leftArm_joint</left_joint_name>
      <right_joint_name>gripper_rightArm_joint</right_joint_name>
    </plugin>
  </gazebo>
  <link name="localization_center">
    <inertial>
      <mass value="0.001"/>
      <origin rpy="0 0 0" xyz="0 0 0"/>
      <inertia ixx="1e-6" ixy="0" ixz="0" iyy="1e-6" iyz="0" izz="1e-6"/>
    </inertial>
  </link>
  <joint name="base_to_localization" type="fixed">
    <parent link="localization_center"/>
    <child link="base_link"/>
    <origin rpy="0 0 0" xyz="0 0 0"/>
  </joint>
  <!-- Camera Link -->
  <link name="front_cam_link">
    <origin rpy="0 0 0" xyz="0 0 0"/>
    <inertial>
      <origin rpy="0 0 0" xyz="0 0 0"/>
      <mass value="0.1"/>
      <inertia ixx="0.001" ixy="0" ixz="0" iyy="0.001" iyz="0" izz="0.001"/>
    </inertial>
  </link>
  <!-- Camera Joint -->
  <joint name="front_cam_joint" type="fixed">
    <origin rpy="0 0 0" xyz="0.78 -0.014274 -0.050"/>
    <parent link="base_link"/>
    <child link="front_cam_link"/>
  </joint>
  <!-- This ensures that the fixed link is not simplified away -->
  <gazebo reference="front_cam_joint">
    <disableFixedJointLumping>true</disableFixedJointLumping>
    <preserveFixedJoint>true</preserveFixedJoint>
  </gazebo>
  <gazebo reference="front_cam_link">
    <sensor name="front_cam_camera" type="rgbd_camera">
      <update_rate>30</update_rate>
      <visualize>true</visualize>
      <always_on>1</always_on>
      <topic>front_cam</topic>
      <camera>
        <horizontal_fov>1.919862177</horizontal_fov>
        <image>
          <width>960</width>
          <height>600</height>
        </image>
        <clip>
          <near>0.1</near>
          <far>50.0</far>
        </clip>
      </camera>
    </sensor>
  </gazebo>
  <!-- Camera Link -->
  <link name="down_cam_link">
    <origin rpy="0 0 0" xyz="0 0 0"/>
    <inertial>
      <origin rpy="0 0 0" xyz="0 0 0"/>
      <mass value="0.1"/>
      <inertia ixx="0.001" ixy="0" ixz="0" iyy="0.001" iyz="0" izz="0.001"/>
    </inertial>
  </link>
  <!-- Camera Joint -->
  <joint name="down_cam_joint" type="fixed">
    <origin rpy="0 1.57 0" xyz="0.45222 0.027913 -0.22"/>
    <parent link="base_link"/>
    <child link="down_cam_link"/>
  </joint>
  <!-- This ensures that the fixed link is not simplified away -->
  <gazebo reference="down_cam_joint">
    <disableFixedJointLumping>true</disableFixedJointLumping>
    <preserveFixedJoint>true</preserveFixedJoint>
  </gazebo>
  <gazebo reference="down_cam_link">
    <sensor name="down_cam_camera" type="rgbd_camera">
      <update_rate>30</update_rate>
      <visualize>true</visualize>
      <always_on>1</always_on>
      <topic>down_cam</topic>
      <camera>
        <horizontal_fov>1.919862177</horizontal_fov>
        <image>
          <width>960</width>
          <height>600</height>
        </image>
        <clip>
          <near>0.1</near>
          <far>50.0</far>
        </clip>
      </camera>
    </sensor>
  </gazebo>
  <!-- DVL Link -->
  <link name="dvl_sensor_link">
    <origin rpy="0 0 0" xyz="0 0 0"/>
    <inertial>
      <origin rpy="0 0 0" xyz="0 0 0"/>
      <mass value="0.1"/>
      <inertia ixx="0.001" ixy="0" ixz="0" iyy="0.001" iyz="0" izz="0.001"/>
    </inertial>
  </link>
  <!-- DVL Joint -->
  <joint name="dvl_sensor_joint" type="fixed">
    <origin rpy="0.0 0.0 0.0" xyz="0.3937 0 -0.2413"/>
    <parent link="base_link"/>
    <child link="dvl_sensor_link"/>
  </joint>
  <!-- This ensures that the fixed link is not simplified away -->
  <gazebo reference="dvl_sensor_joint">
    <disableFixedJointLumping>true</disableFixedJointLumping>
    <preserveFixedJoint>true</preserveFixedJoint>
  </gazebo>
  <!-- Sensor/Plugin Info-->
  <gazebo reference="dvl_sensor_link">
    <sensor gz:type="dvl" name="A50_Waterlinked" type="custom">
      <pose>0 0 0 0 0 0</pose>
      <always_on>1</always_on>
      <update_rate>8</update_rate>
      <topic>/dvl/odom</topic>
      <gz:dvl>
        <type>phased_array</type>
        <arrangement degrees="true">
          <beam id="1">
            <aperture>3</aperture>
            <rotation>-135</rotation>
            <tilt>25</tilt>
          </beam>
          <beam>
            <aperture>3</aperture>
            <rotation>135</rotation>
            <tilt>25</tilt>
          </beam>
          <beam>
            <aperture>3</aperture>
            <rotation>45</rotation>
            <tilt>25</tilt>
          </beam>
          <beam>
            <aperture>3</aperture>
            <rotation>-45</rotation>
            <tilt>25</tilt>
          </beam>
        </arrangement>
        <tracking>
          <water_mass_mode>
            <when>best</when>
            <water_velocity>
              <x>0.</x>
              <y>0.</y>
              <z>0.</z>
            </water_velocity>
            <boundaries>
              <near>10.</near>
              <far>100.</far>
            </boundaries>
            <bins>10</bins>
            <noise type="gaussian">
              <stddev>0.0</stddev>
            </noise>
            <visualize>true</visualize>
          </water_mass_mode>
          <bottom_mode>
            <when>best</when>
            <noise type="gaussian">
              <stddev>0.0</stddev>
            </noise>
            <visualize>true</visualize>
          </bottom_mode>
        </tracking>
        <maximum_range>200.</maximum_range>
        <minimum_range>0.3</minimum_range>
        <!-- ENU to FSD -->
        <reference_frame>0 0 0 0 0 0</reference_frame>
      </gz:dvl>
    </sensor>
  </gazebo>
  <gazebo>
    <plugin filename="DVLBridge" name="dave_ros_gz_plugins::DVLBridge">
      <!-- Grabbed in DVL Bridge script -->
      <topic>/dvl/odom</topic>
    </plugin>
  </gazebo>
  <!-- Imu link -->
  <link name="imu_link">
    <origin rpy="0 0 0" xyz="0 0 0"/>
    <inertial>
      <origin rpy="0 0 0" xyz="0 0 0"/>
      <mass value="0.1"/>
      <inertia ixx="0.001" ixy="0" ixz="0" iyy="0.001" iyz="0" izz="0.001"/>
    </inertial>
  </link>
  <!-- IMU joint -->
  <joint name="imu_joint" type="fixed">
    <origin rpy="0 0 0" xyz="0.65164 -0.00588 0.052145"/>
    <parent link="base_link"/>
    <child link="imu_link"/>
  </joint>
  <!-- This ensures that the fixed link is not simplified away -->
  <gazebo reference="imu_joint">
    <disableFixedJointLumping>true</disableFixedJointLumping>
    <preserveFixedJoint>true</preserveFixedJoint>
  </gazebo>
  <!-- Sensor/Plugin Info-->
  <gazebo reference="imu_link">
    <sensor name="imu_link" type="imu">
      <always_on>true</always_on>
      <update_rate>210</update_rate>
      <topic>/imu/data_raw</topic>
      <gz_frame_id>imu_link</gz_frame_id>
      <imu>
        <linear_acceleration>
          <x>
            <noise type="gaussian">
              <stddev>0.0</stddev>
            </noise>
          </x>
          <y>
            <noise type="gaussian">
              <stddev>0.0</stddev>
            </noise>
          </y>
          <z>
            <noise type="gaussian">
              <stddev>0.0</stddev>
            </noise>
          </z>
        </linear_acceleration>
        <angular_velocity>
          <x>
            <noise type="gaussian">
              <stddev>0.0</stddev>
            </noise>
          </x>
          <y>
            <noise type="gaussian">
              <stddev>0.0</stddev>
            </noise>
          </y>
          <z>
            <noise type="gaussian">
              <stddev>0.0</stddev>
            </noise>
          </z>
        </angular_velocity>
      </imu>
      <plugin filename="gz-sim-imu-system" name="gz::sim::systems::Imu"/>
    </sensor>
    <sensor name="VectorNav_MAG" type="magnetometer">
      <always_on>true</always_on>
      <update_rate>210</update_rate>
      <topic>/imu/mag</topic>
      <plugin filename="gz-sim-magnetometer-system" name="gz::sim::systems::Magnetometer"/>
    </sensor>
  </gazebo>
  <link name="depth_sensor_link">
    <origin rpy="0 0 0" xyz="0 0 0"/>
    <inertial>
      <origin rpy="0 0 0" xyz="0 0 0"/>
      <mass value="0.1"/>
      <inertia ixx="0.001" ixy="0" ixz="0" iyy="0.001" iyz="0" izz="0.001"/>
    </inertial>
  </link>
  <!-- DepthSensor Joint -->
  <joint name="depth_sensor_joint" type="fixed">
    <parent link="base_link"/>
    <child link="depth_sensor_link"/>
    <origin rpy="0 0 0" xyz="0.3 0 0"/>
  </joint>
  <!-- This ensures that the fixed link is not simplified away -->
  <gazebo reference="depth_sensor_joint">
    <disableFixedJointLumping>true</disableFixedJointLumping>
    <preserveFixedJoint>true</preserveFixedJoint>
  </gazebo>
  <gazebo>
    <plugin filename="DepthSensor" name="depth_sensor::DepthSensor">
      <!-- SDF parameters -->
      <frame_id>depth_sensor_link</frame_id>
      <offset>0 0 0 0 0 0</offset>
      <topic>/depth</topic>
      <update_rate>5</update_rate>
      <noise_mean>0.0</noise_mean>
      <noise_stddev>0</noise_stddev>
    </plugin>
  </gazebo>
  <!-- Hydrophone Link -->
  <link name="hydrophone_sensor_link">
    <origin rpy="0 0 0" xyz="0 0 0"/>
    <inertial>
      <origin rpy="0 0 0" xyz="0 0 0"/>
      <mass value="0.1"/>
      <inertia ixx="0.001" ixy="0" ixz="0" iyy="0.001" iyz="0" izz="0.001"/>
    </inertial>
  </link>
  <!-- Hydrophone Joint -->
  <joint name="hydrophone_sensor_joint" type="fixed">
    <origin rpy="0 1.57 .7853981634" xyz="0.10 -0.034274 -0.22"/>
    <parent link="base_link"/>
    <child link="hydrophone_sensor_link"/>
  </joint>
  <!-- This ensures that the fixed link is not simplified away -->
  <gazebo reference="hydrophone_sensor_joint">
    <disableFixedJointLumping>true</disableFixedJointLumping>
    <preserveFixedJoint>true</preserveFixedJoint>
  </gazebo>
  <!-- <gazebo>
      <plugin
        filename="Hydrophone"
        name="hydrophone::Hydrophone">
        <topic>${name}</topic>
      </plugin>
    </gazebo> -->
  <gazebo>
    <preserveFixedJoint>true</preserveFixedJoint>
  </gazebo>
  <!-- The plate link -->
  <link name="asym_drag">
    <inertial>
      <mass value="0.001"/>
      <inertia ixx="0.001" ixy="0" ixz="0" iyy="0.001" iyz="0" izz="0.001"/>
    </inertial>
  </link>
  <!-- Joint (revolute with zero limits avoids fixed-joint reduction reliably) -->
  <joint name="asym_drag_joint" type="revolute">
    <parent link="base_link"/>
    <child link="asym_drag"/>
    <origin xyz="0.8 0 0"/>
    <axis xyz="0 0 1"/>
    <limit effort="0" lower="0" upper="0" velocity="0"/>
  </joint>
  <!-- Hydrodynamics plugin attached to the plate -->
  <gazebo>
    <plugin filename="gz-sim-hydrodynamics-system" name="gz::sim::systems::Hydrodynamics">
      <link_name>asym_drag</link_name>
      <yV>0</yV>
      <yVabsV>0</yVabsV>
      <xU>0</xU>
      <xUabsU>0</xUabsU>
      <zW>0</zW>
      <zWabsW>0</zWabsW>
      <kP>0</kP>
      <kPabsP>0</kPabsP>
      <mQ>0</mQ>
      <mQabsQ>0</mQabsQ>
      <nR>0</nR>
      <nRabsR>0</nRabsR>
    </plugin>
  </gazebo>
  <!-- Gripper Base Link -->
  <link name="gripper_link">
    <origin rpy="0 0 0" xyz="0 0 0"/>
    <inertial>
      <origin rpy="0 0 0" xyz="0 0 0"/>
      <mass value="1.0"/>
      <inertia ixx="0.01" ixy="0" ixz="0" iyy="0.01" iyz="0" izz="0.01"/>
    </inertial>
    <!-- Visual for base -->
    <visual name="gripper_base_visual">
      <geometry>
        <mesh filename="package://subjugator_description/models/gripper_2025/gripper_base.dae"/>
      </geometry>
    </visual>
    <!-- Collision for base -->
    <collision>
      <geometry>
        <box size="0.1 0.1 0.1"/>
      </geometry>
    </collision>
  </link>
  <!-- Left Arm Link  -->
  <link name="gripper_leftArm_link">
    <inertial>
      <origin rpy="0 0 0" xyz="0 0.025 0"/>
      <mass value="0.1"/>
      <inertia ixx="0.001" ixy="0" ixz="0" iyy="0.001" iyz="0" izz="0.001"/>
    </inertial>
    <!-- Left Arm Visual Link -->
    <visual name="gripper_leftArm_visual">
      <origin rpy="1.57 0 -1.57" xyz="0 0.025 -0.3"/>
      <geometry>
        <mesh filename="package://subjugator_description/models/gripper_2025/gripper_arm.dae"/>
      </geometry>
    </visual>
    <!-- Left fingertip collision: small rectangular box for reliable contact -->
    <collision name="leftArm_collision">
      <!-- positioned near the visual fingertip; adjust if needed -->
      <origin rpy="0 0 0" xyz="0 0.045 0"/>
      <geometry>
        <box>
          <size>0.1 0.1 0.1</size>
        </box>
      </geometry>
    </collision>
  </link>
  <!-- Left Arm Joint -->
  <joint name="gripper_leftArm_joint" type="revolute">
    <origin rpy="0 0 0" xyz="0 0.025 0"/>
    <parent link="gripper_link"/>
    <child link="gripper_leftArm_link"/>
    <axis xyz="1 0 0"/>
    <limit effort="1.0" lower="0.0" upper="0.5" velocity="1.0"/>
  </joint>
  <!-- Right Arm Link -->
  <link name="gripper_rightArm_link">
    <inertial>
      <origin rpy="0 0 0" xyz="0 -0.025 0"/>
      <mass value="0.1"/>
      <inertia ixx="0.001" ixy="0" ixz="0" iyy="0.001" iyz="0" izz="0.001"/>
    </inertial>
    <!-- Right Arm Visual Link -->
    <visual name="gripper_rightArm_visual">
      <origin rpy="1.57 0 1.57" xyz="0 -0.025 -0.3"/>
      <geometry>
        <mesh filename="package://subjugator_description/models/gripper_2025/gripper_arm.dae"/>
      </geometry>
    </visual>
    <!-- Right fingertip collision: small rectangular box for reliable contact -->
    <collision name="rightArm_collision">
      <!-- positioned near the visual fingertip; adjust if needed -->
      <origin rpy="0 0 0" xyz="0 -0.045 0"/>
      <geometry>
        <box>
          <size>0.1 0.1 0.1</size>
        </box>
      </geometry>
    </collision>
  </link>
  <!-- Right Arm Joint -->
  <joint name="gripper_rightArm_joint" type="revolute">
    <origin rpy="0 0 0" xyz="0 -0.025 0"/>
    <parent link="gripper_link"/>
    <child link="gripper_rightArm_link"/>
    <axis xyz="-1 0 0"/>
    <limit effort="1.0" lower="0.0" upper="0.5" velocity="1.0"/>
  </joint>
  <!-- Fixed Joint to Parent -->
  <joint name="gripper_joint" type="fixed">
    <origin rpy="0 0 0" xyz="0.375 0 -0.225"/>
    <parent link="base_link"/>
    <child link="gripper_link"/>
  </joint>
  <gazebo reference="gripper_joint">
    <disableFixedJointLumping>true</disableFixedJointLumping>
    <preserveFixedJoint>true</preserveFixedJoint>
  </gazebo>
  <!-- Link for base of thruster (this is for TF) -->
  <link name="FLV_link">
    <origin rpy="0 0 0" xyz="0 0 0"/>
    <inertial>
      <origin rpy="0 0 0" xyz="0 0 0"/>
      <mass value="0.01"/>
      <inertia ixx="0.001" ixy="0" ixz="0" iyy="0.001" iyz="0" izz="0.001"/>
    </inertial>
  </link>
  <!-- Thruster base Joint -->
  <joint name="FLV_joint" type="fixed">
    <origin rpy="0 -1.5708 0" xyz="0.5715 0.14922 -0.028575"/>
    <parent link="base_link"/>
    <child link="FLV_link"/>
  </joint>
  <!-- This ensures that the fixed link is not simplified away -->
  <gazebo reference="FLV_joint">
    <disableFixedJointLumping>true</disableFixedJointLumping>
    <preserveFixedJoint>true</preserveFixedJoint>
  </gazebo>
  <!-- Thruster Direction link (this is for the plugin) -->
  <!-- The plugin does not work with a fixed link -->
  <link name="FLV_dir_link">
    <origin rpy="0 0 0" xyz="0 0 0"/>
    <inertial>
      <origin rpy="0 0 0" xyz="0 0 0"/>
      <mass value="0.01"/>
      <inertia ixx="0.001" ixy="0" ixz="0" iyy="0.001" iyz="0" izz="0.001"/>
    </inertial>
  </link>
  <!-- Thruster Direction joint -->
  <joint name="FLV_dir_joint" type="revolute">
    <origin rpy="0 0 0" xyz="0 0 0"/>
    <parent link="FLV_link"/>
    <child link="FLV_dir_link"/>
    <limit effort="1000" lower="0.0" upper="0.548" velocity="0.5"/>
  </joint>
  <!-- Sensor/Plugin Info-->
  <!-- For the thruster plugin this gazebo tag needs to be global-->
  <!-- Don't give it a reference like the other plugins-->
  <gazebo>
    <plugin filename="gz-sim-thruster-system" name="gz::sim::systems::Thruster">
      <namespace>FLV</namespace>
      <use_angvel_cmd>0</use_angvel_cmd>
      <joint_name>FLV_dir_joint</joint_name>
      <thrust_coefficient>0.01407</thrust_coefficient>
      <fluid_density>1000</fluid_density>
      <propeller_diameter>0.2</propeller_diameter>
    </plugin>
  </gazebo>
  <!-- Link for base of thruster (this is for TF) -->
  <link name="FRV_link">
    <origin rpy="0 0 0" xyz="0 0 0"/>
    <inertial>
      <origin rpy="0 0 0" xyz="0 0 0"/>
      <mass value="0.01"/>
      <inertia ixx="0.001" ixy="0" ixz="0" iyy="0.001" iyz="0" izz="0.001"/>
    </inertial>
  </link>
  <!-- Thruster base Joint -->
  <joint name="FRV_joint" type="fixed">
    <origin rpy="0 -1.5708 0" xyz="0.5715 -0.14922 -0.028575"/>
    <parent link="base_link"/>
    <child link="FRV_link"/>
  </joint>
  <!-- This ensures that the fixed link is not simplified away -->
  <gazebo reference="FRV_joint">
    <disableFixedJointLumping>true</disableFixedJointLumping>
    <preserveFixedJoint>true</preserveFixedJoint>
  </gazebo>
  <!-- Thruster Direction link (this is for the plugin) -->
  <!-- The plugin does not work with a fixed link -->
  <link name="FRV_dir_link">
    <origin rpy="0 0 0" xyz="0 0 0"/>
    <inertial>
      <origin rpy="0 0 0" xyz="0 0 0"/>
      <mass value="0.01"/>
      <inertia ixx="0.001" ixy="0" ixz="0" iyy="0.001" iyz="0" izz="0.001"/>
    </inertial>
  </link>
  <!-- Thruster Direction joint -->
  <joint name="FRV_dir_joint" type="revolute">
    <origin rpy="0 0 0" xyz="0 0 0"/>
    <parent link="FRV_link"/>
    <child link="FRV_dir_link"/>
    <limit effort="1000" lower="0.0" upper="0.548" velocity="0.5"/>
  </joint>
  <!-- Sensor/Plugin Info-->
  <!-- For the thruster plugin this gazebo tag needs to be global-->
  <!-- Don't give it a reference like the other plugins-->
  <gazebo>
    <plugin filename="gz-sim-thruster-system" name="gz::sim::systems::Thruster">
      <namespace>FRV</namespace>
      <use_angvel_cmd>0</use_angvel_cmd>
      <joint_name>FRV_dir_joint</joint_name>
      <thrust_coefficient>0.01407</thrust_coefficient>
      <fluid_density>1000</fluid_density>
      <propeller_diameter>0.2</propeller_diameter>
    </plugin>
  </gazebo>
  <!-- Link for base of thruster (this is for TF) -->
  <link name="BRV_link">
    <origin rpy="0 0 0" xyz="0 0 0"/>
    <inertial>
      <origin rpy="0 0 0" xyz="0 0 0"/>
      <mass value="0.01"/>
      <inertia ixx="0.001" ixy="0" ixz="0" iyy="0.001" iyz="0" izz="0.001"/>
    </inertial>
  </link>
  <!-- Thruster base Joint -->
  <joint name="BRV_joint" type="fixed">
    <origin rpy="0 -1.5708 0" xyz="0.1143 -0.14922 -0.028575"/>
    <parent link="base_link"/>
    <child link="BRV_link"/>
  </joint>
  <!-- This ensures that the fixed link is not simplified away -->
  <gazebo reference="BRV_joint">
    <disableFixedJointLumping>true</disableFixedJointLumping>
    <preserveFixedJoint>true</preserveFixedJoint>
  </gazebo>
  <!-- Thruster Direction link (this is for the plugin) -->
  <!-- The plugin does not work with a fixed link -->
  <link name="BRV_dir_link">
    <origin rpy="0 0 0" xyz="0 0 0"/>
    <inertial>
      <origin rpy="0 0 0" xyz="0 0 0"/>
      <mass value="0.01"/>
      <inertia ixx="0.001" ixy="0" ixz="0" iyy="0.001" iyz="0" izz="0.001"/>
    </inertial>
  </link>
  <!-- Thruster Direction joint -->
  <joint name="BRV_dir_joint" type="revolute">
    <origin rpy="0 0 0" xyz="0 0 0"/>
    <parent link="BRV_link"/>
    <child link="BRV_dir_link"/>
    <limit effort="1000" lower="0.0" upper="0.548" velocity="0.5"/>
  </joint>
  <!-- Sensor/Plugin Info-->
  <!-- For the thruster plugin this gazebo tag needs to be global-->
  <!-- Don't give it a reference like the other plugins-->
  <gazebo>
    <plugin filename="gz-sim-thruster-system" name="gz::sim::systems::Thruster">
      <namespace>BRV</namespace>
      <use_angvel_cmd>0</use_angvel_cmd>
      <joint_name>BRV_dir_joint</joint_name>
      <thrust_coefficient>0.01407</thrust_coefficient>
      <fluid_density>1000</fluid_density>
      <propeller_diameter>0.2</propeller_diameter>
    </plugin>
  </gazebo>
  <!-- Link for base of thruster (this is for TF) -->
  <link name="BLV_link">
    <origin rpy="0 0 0" xyz="0 0 0"/>
    <inertial>
      <origin rpy="0 0 0" xyz="0 0 0"/>
      <mass value="0.01"/>
      <inertia ixx="0.001" ixy="0" ixz="0" iyy="0.001" iyz="0" izz="0.001"/>
    </inertial>
  </link>
  <!-- Thruster base Joint -->
  <joint name="BLV_joint" type="fixed">
    <origin rpy="0 -1.5708 0" xyz="0.1143 0.14922 -0.028575"/>
    <parent link="base_link"/>
    <child link="BLV_link"/>
  </joint>
  <!-- This ensures that the fixed link is not simplified away -->
  <gazebo reference="BLV_joint">
    <disableFixedJointLumping>true</disableFixedJointLumping>
    <preserveFixedJoint>true</preserveFixedJoint>
  </gazebo>
  <!-- Thruster Direction link (this is for the plugin) -->
  <!-- The plugin does not work with a fixed link -->
  <link name="BLV_dir_link">
    <origin rpy="0 0 0" xyz="0 0 0"/>
    <inertial>
      <origin rpy="0 0 0" xyz="0 0 0"/>
      <mass value="0.01"/>
      <inertia ixx="0.001" ixy="0" ixz="0" iyy="0.001" iyz="0" izz="0.001"/>
    </inertial>
  </link>
  <!-- Thruster Direction joint -->
  <joint name="BLV_dir_joint" type="revolute">
    <origin rpy="0 0 0" xyz="0 0 0"/>
    <parent link="BLV_link"/>
    <child link="BLV_dir_link"/>
    <limit effort="1000" lower="0.0" upper="0.548" velocity="0.5"/>
  </joint>
  <!-- Sensor/Plugin Info-->
  <!-- For the thruster plugin this gazebo tag needs to be global-->
  <!-- Don't give it a reference like the other plugins-->
  <gazebo>
    <plugin filename="gz-sim-thruster-system" name="gz::sim::systems::Thruster">
      <namespace>BLV</namespace>
      <use_angvel_cmd>0</use_angvel_cmd>
      <joint_name>BLV_dir_joint</joint_name>
      <thrust_coefficient>0.01407</thrust_coefficient>
      <fluid_density>1000</fluid_density>
      <propeller_diameter>0.2</propeller_diameter>
    </plugin>
  </gazebo>
  <!-- Link for base of thruster (this is for TF) -->
  <link name="FLH_link">
    <origin rpy="0 0 0" xyz="0 0 0"/>
    <inertial>
      <origin rpy="0 0 0" xyz="0 0 0"/>
      <mass value="0.01"/>
      <inertia ixx="0.001" ixy="0" ixz="0" iyy="0.001" iyz="0" izz="0.001"/>
    </inertial>
  </link>
  <!-- Thruster base Joint -->
  <joint name="FLH_joint" type="fixed">
    <origin rpy="0 0 -0.523598776" xyz="0.58737 0.24765 0.053975"/>
    <parent link="base_link"/>
    <child link="FLH_link"/>
  </joint>
  <!-- This ensures that the fixed link is not simplified away -->
  <gazebo reference="FLH_joint">
    <disableFixedJointLumping>true</disableFixedJointLumping>
    <preserveFixedJoint>true</preserveFixedJoint>
  </gazebo>
  <!-- Thruster Direction link (this is for the plugin) -->
  <!-- The plugin does not work with a fixed link -->
  <link name="FLH_dir_link">
    <origin rpy="0 0 0" xyz="0 0 0"/>
    <inertial>
      <origin rpy="0 0 0" xyz="0 0 0"/>
      <mass value="0.01"/>
      <inertia ixx="0.001" ixy="0" ixz="0" iyy="0.001" iyz="0" izz="0.001"/>
    </inertial>
  </link>
  <!-- Thruster Direction joint -->
  <joint name="FLH_dir_joint" type="revolute">
    <origin rpy="0 0 0" xyz="0 0 0"/>
    <parent link="FLH_link"/>
    <child link="FLH_dir_link"/>
    <limit effort="1000" lower="0.0" upper="0.548" velocity="0.5"/>
  </joint>
  <!-- Sensor/Plugin Info-->
  <!-- For the thruster plugin this gazebo tag needs to be global-->
  <!-- Don't give it a reference like the other plugins-->
  <gazebo>
    <plugin filename="gz-sim-thruster-system" name="gz::sim::systems::Thruster">
      <namespace>FLH</namespace>
      <use_angvel_cmd>0</use_angvel_cmd>
      <joint_name>FLH_dir_joint</joint_name>
      <thrust_coefficient>0.01407</thrust_coefficient>
      <fluid_density>1000</fluid_density>
      <propeller_diameter>0.2</propeller_diameter>
    </plugin>
  </gazebo>
  <!-- Link for base of thruster (this is for TF) -->
  <link name="FRH_link">
    <origin rpy="0 0 0" xyz="0 0 0"/>
    <inertial>
      <origin rpy="0 0 0" xyz="0 0 0"/>
      <mass value="0.01"/>
      <inertia ixx="0.001" ixy="0" ixz="0" iyy="0.001" iyz="0" izz="0.001"/>
    </inertial>
  </link>
  <!-- Thruster base Joint -->
  <joint name="FRH_joint" type="fixed">
    <origin rpy="0 0 0.523598776" xyz="0.58737 -0.24765 0.053975"/>
    <parent link="base_link"/>
    <child link="FRH_link"/>
  </joint>
  <!-- This ensures that the fixed link is not simplified away -->
  <gazebo reference="FRH_joint">
    <disableFixedJointLumping>true</disableFixedJointLumping>
    <preserveFixedJoint>true</preserveFixedJoint>
  </gazebo>
  <!-- Thruster Direction link (this is for the plugin) -->
  <!-- The plugin does not work with a fixed link -->
  <link name="FRH_dir_link">
    <origin rpy="0 0 0" xyz="0 0 0"/>
    <inertial>
      <origin rpy="0 0 0" xyz="0 0 0"/>
      <mass value="0.01"/>
      <inertia ixx="0.001" ixy="0" ixz="0" iyy="0.001" iyz="0" izz="0.001"/>
    </inertial>
  </link>
  <!-- Thruster Direction joint -->
  <joint name="FRH_dir_joint" type="revolute">
    <origin rpy="0 0 0" xyz="0 0 0"/>
    <parent link="FRH_link"/>
    <child link="FRH_dir_link"/>
    <limit effort="1000" lower="0.0" upper="0.548" velocity="0.5"/>
  </joint>
  <!-- Sensor/Plugin Info-->
  <!-- For the thruster plugin this gazebo tag needs to be global-->
  <!-- Don't give it a reference like the other plugins-->
  <gazebo>
    <plugin filename="gz-sim-thruster-system" name="gz::sim::systems::Thruster">
      <namespace>FRH</namespace>
      <use_angvel_cmd>0</use_angvel_cmd>
      <joint_name>FRH_dir_joint</joint_name>
      <thrust_coefficient>0.01407</thrust_coefficient>
      <fluid_density>1000</fluid_density>
      <propeller_diameter>0.2</propeller_diameter>
    </plugin>
  </gazebo>
  <!-- Link for base of thruster (this is for TF) -->
  <link name="BRH_link">
    <origin rpy="0 0 0" xyz="0 0 0"/>
    <inertial>
      <origin rpy="0 0 0" xyz="0 0 0"/>
      <mass value="0.01"/>
      <inertia ixx="0.001" ixy="0" ixz="0" iyy="0.001" iyz="0" izz="0.001"/>
    </inertial>
  </link>
  <!-- Thruster base Joint -->
  <joint name="BRH_joint" type="fixed">
    <origin rpy="0 0 -0.523598776" xyz="0.127 -0.24765 0.053975"/>
    <parent link="base_link"/>
    <child link="BRH_link"/>
  </joint>
  <!-- This ensures that the fixed link is not simplified away -->
  <gazebo reference="BRH_joint">
    <disableFixedJointLumping>true</disableFixedJointLumping>
    <preserveFixedJoint>true</preserveFixedJoint>
  </gazebo>
  <!-- Thruster Direction link (this is for the plugin) -->
  <!-- The plugin does not work with a fixed link -->
  <link name="BRH_dir_link">
    <origin rpy="0 0 0" xyz="0 0 0"/>
    <inertial>
      <origin rpy="0 0 0" xyz="0 0 0"/>
      <mass value="0.01"/>
      <inertia ixx="0.001" ixy="0" ixz="0" iyy="0.001" iyz="0" izz="0.001"/>
    </inertial>
  </link>
  <!-- Thruster Direction joint -->
  <joint name="BRH_dir_joint" type="revolute">
    <origin rpy="0 0 0" xyz="0 0 0"/>
    <parent link="BRH_link"/>
    <child link="BRH_dir_link"/>
    <limit effort="1000" lower="0.0" upper="0.548" velocity="0.5"/>
  </joint>
  <!-- Sensor/Plugin Info-->
  <!-- For the thruster plugin this gazebo tag needs to be global-->
  <!-- Don't give it a reference like the other plugins-->
  <gazebo>
    <plugin filename="gz-sim-thruster-system" name="gz::sim::systems::Thruster">
      <namespace>BRH</namespace>
      <use_angvel_cmd>0</use_angvel_cmd>
      <joint_name>BRH_dir_joint</joint_name>
      <thrust_coefficient>0.01407</thrust_coefficient>
      <fluid_density>1000</fluid_density>
      <propeller_diameter>0.2</propeller_diameter>
    </plugin>
  </gazebo>
  <!-- Link for base of thruster (this is for TF) -->
  <link name="BLH_link">
    <origin rpy="0 0 0" xyz="0 0 0"/>
    <inertial>
      <origin rpy="0 0 0" xyz="0 0 0"/>
      <mass value="0.01"/>
      <inertia ixx="0.001" ixy="0" ixz="0" iyy="0.001" iyz="0" izz="0.001"/>
    </inertial>
  </link>
  <!-- Thruster base Joint -->
  <joint name="BLH_joint" type="fixed">
    <origin rpy="0 0 0.523598776" xyz="0.127 0.24765 0.053975"/>
    <parent link="base_link"/>
    <child link="BLH_link"/>
  </joint>
  <!-- This ensures that the fixed link is not simplified away -->
  <gazebo reference="BLH_joint">
    <disableFixedJointLumping>true</disableFixedJointLumping>
    <preserveFixedJoint>true</preserveFixedJoint>
  </gazebo>
  <!-- Thruster Direction link (this is for the plugin) -->
  <!-- The plugin does not work with a fixed link -->
  <link name="BLH_dir_link">
    <origin rpy="0 0 0" xyz="0 0 0"/>
    <inertial>
      <origin rpy="0 0 0" xyz="0 0 0"/>
      <mass value="0.01"/>
      <inertia ixx="0.001" ixy="0" ixz="0" iyy="0.001" iyz="0" izz="0.001"/>
    </inertial>
  </link>
  <!-- Thruster Direction joint -->
  <joint name="BLH_dir_joint" type="revolute">
    <origin rpy="0 0 0" xyz="0 0 0"/>
    <parent link="BLH_link"/>
    <child link="BLH_dir_link"/>
    <limit effort="1000" lower="0.0" upper="0.548" velocity="0.5"/>
  </joint>
  <!-- Sensor/Plugin Info-->
  <!-- For the thruster plugin this gazebo tag needs to be global-->
  <!-- Don't give it a reference like the other plugins-->
  <gazebo>
    <plugin filename="gz-sim-thruster-system" name="gz::sim::systems::Thruster">
      <namespace>BLH</namespace>
      <use_angvel_cmd>0</use_angvel_cmd>
      <joint_name>BLH_dir_joint</joint_name>
      <thrust_coefficient>0.01407</thrust_coefficient>
      <fluid_density>1000</fluid_density>
      <propeller_diameter>0.2</propeller_diameter>
    </plugin>
  </gazebo>
</robot>
